# Redis Configuration and User ID Fix Summary

## Issues Fixed

### 1. Redis Cache Configuration Error

**Error:** `__init__() got an unexpected keyword argument 'CONNECTION_POOL_KWARGS'`

**Root Cause:** The Django Redis cache backend configuration was using options that aren't supported by the built-in `django.core.cache.backends.redis.RedisCache` backend in Django 4.2.

**Fix Applied:**

- Removed `CLIENT_CLASS` option (not needed for built-in Redis backend)
- Removed `CONNECTION_POOL_KWARGS` nested configuration
- Removed `socket_connect_timeout` and `socket_timeout` options
- Simplified to basic configuration with only `BACKEND`, `LOCATION`, `KEY_PREFIX`, and `TIMEOUT`

**File Modified:** `god_bless_backend/god_bless_pro/settings.py`

### 2. User ID Lookup Error in Celery Tasks

**Error:** `User 1 not found for task [task_id]` / `User matching query does not exist`

**Root Cause:**

- The User model has two ID fields: `id` (auto-generated primary key) and `user_id` (custom CharField)
- Views were passing `user.id` (primary key) to Celery tasks
- Celery tasks were trying to look up users with `User.objects.get(user_id=user_id)` which expects the `user_id` field, not the `id` field

**Fix Applied:**

- Changed all Celery task calls in views to pass `user.user_id` instead of `user.id`
- This ensures the correct field is used for user lookup in background tasks

**File Modified:** `god_bless_backend/phone_generator/api/views.py`

**Affected Functions:**

- `generate_numbers_view` - Legacy phone generation endpoint
- `generate_numbers_enhanced_view` - Enhanced phone generation
- `validate_numbers_enhanced_view` - Phone validation
- `bulk_validate_phone_numbers_view` - Bulk validation
- `generate_numbers_with_config_view` (multiple instances) - Advanced generation
- `export_phone_numbers_view` - Export functionality
- `import_phone_numbers_view` - Import functionality
- `import_sms_recipients_view` - SMS recipient import

## Next Steps

### 1. Restart Services

To apply these fixes, restart your Docker containers:

```cmd
cd god_bless_backend
docker-compose restart backend celery celery-beat
```

Or for a full restart:

```cmd
stop-local.cmd
start-local.cmd
```

### 2. Create a User (if needed)

If you don't have any users in your database, create a superuser:

```cmd
docker exec -it god_bless_app python manage.py createsuperuser
```

### 3. Test the Fix

Try generating phone numbers again through the API endpoint:

- POST to `/api/phone-generator/generate-numbers-config/`
- The Redis error should be gone
- The user lookup error should be resolved

## Technical Details

### Redis Cache Configuration (Before)

```python
CACHES = {
    'default': {
        'BACKEND': 'django.core.cache.backends.redis.RedisCache',
        'LOCATION': REDIS_URL,
        'OPTIONS': {
            'CLIENT_CLASS': 'django_redis.client.DefaultClient',  # ❌ Not supported
            'CONNECTION_POOL_KWARGS': {  # ❌ Not supported
                'max_connections': 50,
                'retry_on_timeout': True,
            },
            'SOCKET_CONNECT_TIMEOUT': 5,  # ❌ Wrong case
            'SOCKET_TIMEOUT': 5,  # ❌ Wrong case
        },
        'KEY_PREFIX': 'godbless',
        'TIMEOUT': 300,
    }
}
```

### Redis Cache Configuration (After)

```python
CACHES = {
    'default': {
        'BACKEND': 'django.core.cache.backends.redis.RedisCache',
        'LOCATION': REDIS_URL,
        'KEY_PREFIX': 'godbless',
        'TIMEOUT': 300,  # Default timeout: 5 minutes
    }
}
```

### User ID Fix (Before)

```python
task = generate_phone_numbers_task.delay(
    user_id=user.id,  # ❌ Passes primary key (1, 2, 3...)
    project_id=project.id,
    ...
)
```

### User ID Fix (After)

```python
task = generate_phone_numbers_task.delay(
    user_id=user.user_id,  # ✅ Passes custom user_id field
    project_id=project.id,
    ...
)
```

## Date Fixed

October 5, 2025

### 3. Missing WebSocket Notification Method

**Error:** `'generate_phone_numbers_task' object has no attribute '_send_task_notification'`

**Root Cause:**

- The Celery tasks were calling `self._send_task_notification()` method
- This method was defined inside each task function instead of in the base class
- The method wasn't accessible when called at the beginning of the task

**Fix Applied:**

- Added `_send_task_notification` method to the `ProgressTrackingTask` base class in `tasks/base.py`
- Removed duplicate method definitions from individual task functions (3 instances)
- Now all tasks inheriting from `ProgressTrackingTask` have access to this method

**Files Modified:**

- `god_bless_backend/tasks/base.py` - Added the method to base class
- `god_bless_backend/phone_generator/tasks.py` - Removed duplicate definitions

---

## All Fixes Complete

All three errors have been resolved:

1. ✅ Redis `CONNECTION_POOL_KWARGS` error
2. ✅ User lookup error (user.id vs user.user_id)
3. ✅ Missing `_send_task_notification` method

**Final Step:** Restart your services one more time to apply all fixes:

```cmd
cd god_bless_backend
docker-compose restart backend celery celery-beat
```

Then test phone number generation - it should work completely now!
